2019-12-18 15:11:27,707 - __main__ - WARNING - Something maybe fail.
2019-12-18 15:11:27,709 - __main__ - ERROR - Fail to open sdfs.txt from logger.error
Traceback (most recent call last):
  File "logging_test.py", line 40, in <module>
    open('sdfs.txt', 'rb')
FileNotFoundError: [Errno 2] No such file or directory: 'sdfs.txt'
